<sdf version='1.7'>
  <world name='default'>
    <light name='sun' type='directional'>
      <cast_shadows>1</cast_shadows>
      <pose>0 0 10 0 -0 0</pose>
      <diffuse>0.8 0.8 0.8 1</diffuse>
      <specular>0.2 0.2 0.2 1</specular>
      <attenuation>
        <range>1000</range>
        <constant>0.9</constant>
        <linear>0.01</linear>
        <quadratic>0.001</quadratic>
      </attenuation>
      <direction>-0.5 0.1 -0.9</direction>
      <spot>
        <inner_angle>0</inner_angle>
        <outer_angle>0</outer_angle>
        <falloff>0</falloff>
      </spot>
    </light>
    <model name='ground_plane'>
      <static>1</static>
      <link name='link'>
        <collision name='collision'>
          <geometry>
            <plane>
              <normal>0 0 1</normal>
              <size>100 100</size>
            </plane>
          </geometry>
          <surface>
            <contact>
              <collide_bitmask>65535</collide_bitmask>
              <ode/>
            </contact>
            <friction>
              <ode>
                <mu>100</mu>
                <mu2>50</mu2>
              </ode>
              <torsional>
                <ode/>
              </torsional>
            </friction>
            <bounce/>
          </surface>
          <max_contacts>10</max_contacts>
        </collision>
        <visual name='visual'>
          <cast_shadows>0</cast_shadows>
          <geometry>
            <plane>
              <normal>0 0 1</normal>
              <size>100 100</size>
            </plane>
          </geometry>
          <material>
            <script>
              <uri>file://media/materials/scripts/gazebo.material</uri>
              <name>Gazebo/Grey</name>
            </script>
          </material>
        </visual>
        <self_collide>0</self_collide>
        <enable_wind>0</enable_wind>
        <kinematic>0</kinematic>
      </link>
    </model>
    <gravity>0 0 -9.8</gravity>
    <magnetic_field>6e-06 2.3e-05 -4.2e-05</magnetic_field>
    <atmosphere type='adiabatic'/>
    <physics type='ode'>
      <max_step_size>0.001</max_step_size>
      <real_time_factor>1</real_time_factor>
      <real_time_update_rate>1000</real_time_update_rate>
    </physics>
    <scene>
      <ambient>0.4 0.4 0.4 1</ambient>
      <background>0.7 0.7 0.7 1</background>
      <shadows>1</shadows>
    </scene>
    <wind/>
    <spherical_coordinates>
      <surface_model>EARTH_WGS84</surface_model>
      <latitude_deg>0</latitude_deg>
      <longitude_deg>0</longitude_deg>
      <elevation>0</elevation>
      <heading_deg>0</heading_deg>
    </spherical_coordinates>
    <model name='sentry'>
      <link name='base_link'>
        <inertial>
          <pose>0.00322 0.014441 0.043408 0 -0 0</pose>
          <mass>9.16</mass>
          <inertia>
            <ixx>0.2298</ixx>
            <ixy>0.0007142</ixy>
            <ixz>0.01441</ixz>
            <iyy>0.2387</iyy>
            <iyz>0.01056</iyz>
            <izz>0.3928</izz>
          </inertia>
        </inertial>
        <collision name='base_link_collision'>
          <pose>0 0 0.04 0 -0 0</pose>
          <geometry>
            <box>
              <size>0.615 0.62 0.3</size>
            </box>
          </geometry>
          <max_contacts>10</max_contacts>
          <surface>
            <contact>
              <ode/>
            </contact>
            <bounce/>
            <friction>
              <torsional>
                <ode/>
              </torsional>
              <ode/>
            </friction>
          </surface>
        </collision>
        <visual name='base_link_visual'>
          <pose>0 0 0 0 -0 0</pose>
          <geometry>
            <mesh>
              <scale>1 1 1</scale>
              <uri>/home/idris/final_ws/src/rm_description_for_task/meshes/sentry/base.stl</uri>
            </mesh>
          </geometry>
        </visual>
        <self_collide>0</self_collide>
        <enable_wind>0</enable_wind>
        <kinematic>0</kinematic>
      </link>
      <joint name='left_back_pivot_joint' type='revolute'>
        <pose relative_to='base_link'>-0.181 0.181 0.013 0 -0 0</pose>
        <parent>base_link</parent>
        <child>left_back_pivot</child>
        <axis>
          <xyz>0 0 1</xyz>
          <limit>
            <lower>-1e+10</lower>
            <upper>1e+10</upper>
            <effort>1.2</effort>
            <velocity>50</velocity>
          </limit>
          <dynamics>
            <damping>0</damping>
            <friction>0.1</friction>
            <spring_reference>0</spring_reference>
            <spring_stiffness>0</spring_stiffness>
          </dynamics>
        </axis>
      </joint>
      <link name='left_back_pivot'>
        <pose relative_to='left_back_pivot_joint'>0 0 0 0 -0 0</pose>
        <inertial>
          <pose>-5e-05 0.017079 -0.041536 0 -0 0</pose>
          <mass>0.114131</mass>
          <inertia>
            <ixx>0.0001335</ixx>
            <ixy>2.6001e-08</ixy>
            <ixz>6.5031e-08</ixz>
            <iyy>0.0001372</iyy>
            <iyz>2.00517e-05</iyz>
            <izz>6.68661e-05</izz>
          </inertia>
        </inertial>
        <visual name='left_back_pivot_visual'>
          <pose>0 0 0 0 -0 0</pose>
          <geometry>
            <mesh>
              <scale>0.001 0.001 0.001</scale>
              <uri>/home/idris/final_ws/src/rm_description_for_task/meshes/common/swerve_pivot.stl</uri>
            </mesh>
          </geometry>
        </visual>
        <self_collide>0</self_collide>
        <enable_wind>0</enable_wind>
        <kinematic>0</kinematic>
      </link>
      <joint name='left_back_wheel_joint' type='revolute'>
        <pose relative_to='left_back_pivot'>0 0 -0.07735 0 -0 0</pose>
        <parent>left_back_pivot</parent>
        <child>left_back_wheel</child>
        <axis>
          <xyz>0 1 0</xyz>
          <limit>
            <lower>-1e+10</lower>
            <upper>1e+10</upper>
            <effort>3</effort>
            <velocity>100</velocity>
          </limit>
          <dynamics>
            <damping>0</damping>
            <friction>0.05</friction>
            <spring_reference>0</spring_reference>
            <spring_stiffness>0</spring_stiffness>
          </dynamics>
        </axis>
      </joint>
      <link name='left_back_wheel'>
        <pose relative_to='left_back_wheel_joint'>0 0 0 0 -0 0</pose>
        <inertial>
          <pose>-4e-06 0.000125 1e-06 0 -0 0</pose>
          <mass>0.267401</mass>
          <inertia>
            <ixx>0.0003585</ixx>
            <ixy>0</ixy>
            <ixz>1.3459e-08</ixz>
            <iyy>0.0006846</iyy>
            <iyz>0</iyz>
            <izz>0.0003584</izz>
          </inertia>
        </inertial>
        <collision name='left_back_wheel_collision'>
          <pose>0 0 0 1.5708 -0 0</pose>
          <geometry>
            <cylinder>
              <length>0.02</length>
              <radius>0.055</radius>
            </cylinder>
          </geometry>
          <surface>
            <contact>
              <ode>
                <kp>1e+06</kp>
                <kd>100</kd>
              </ode>
            </contact>
            <friction>
              <ode>
                <mu>1</mu>
                <mu2>1</mu2>
              </ode>
              <torsional>
                <ode/>
              </torsional>
            </friction>
            <bounce/>
          </surface>
          <max_contacts>10</max_contacts>
        </collision>
        <visual name='left_back_wheel_visual'>
          <pose>0 0 0 0 -0 0</pose>
          <geometry>
            <mesh>
              <scale>0.001 0.001 0.001</scale>
              <uri>/home/idris/final_ws/src/rm_description_for_task/meshes/common/swerve_wheel.stl</uri>
            </mesh>
          </geometry>
          <material>
            <script>
              <name>Gazebo/Black</name>
              <uri>file://media/materials/scripts/gazebo.material</uri>
            </script>
          </material>
        </visual>
        <self_collide>0</self_collide>
        <enable_wind>0</enable_wind>
        <kinematic>0</kinematic>
      </link>
      <joint name='left_front_pivot_joint' type='revolute'>
        <pose relative_to='base_link'>0.181 0.181 0.013 0 -0 0</pose>
        <parent>base_link</parent>
        <child>left_front_pivot</child>
        <axis>
          <xyz>0 0 1</xyz>
          <limit>
            <lower>-1e+10</lower>
            <upper>1e+10</upper>
            <effort>1.2</effort>
            <velocity>50</velocity>
          </limit>
          <dynamics>
            <damping>0</damping>
            <friction>0.1</friction>
            <spring_reference>0</spring_reference>
            <spring_stiffness>0</spring_stiffness>
          </dynamics>
        </axis>
      </joint>
      <link name='left_front_pivot'>
        <pose relative_to='left_front_pivot_joint'>0 0 0 0 -0 0</pose>
        <inertial>
          <pose>-5e-05 0.017079 -0.041536 0 -0 0</pose>
          <mass>0.114131</mass>
          <inertia>
            <ixx>0.0001335</ixx>
            <ixy>2.6001e-08</ixy>
            <ixz>6.5031e-08</ixz>
            <iyy>0.0001372</iyy>
            <iyz>2.00517e-05</iyz>
            <izz>6.68661e-05</izz>
          </inertia>
        </inertial>
        <visual name='left_front_pivot_visual'>
          <pose>0 0 0 0 -0 0</pose>
          <geometry>
            <mesh>
              <scale>0.001 0.001 0.001</scale>
              <uri>/home/idris/final_ws/src/rm_description_for_task/meshes/common/swerve_pivot.stl</uri>
            </mesh>
          </geometry>
        </visual>
        <self_collide>0</self_collide>
        <enable_wind>0</enable_wind>
        <kinematic>0</kinematic>
      </link>
      <joint name='left_front_wheel_joint' type='revolute'>
        <pose relative_to='left_front_pivot'>0 0 -0.07735 0 -0 0</pose>
        <parent>left_front_pivot</parent>
        <child>left_front_wheel</child>
        <axis>
          <xyz>0 1 0</xyz>
          <limit>
            <lower>-1e+10</lower>
            <upper>1e+10</upper>
            <effort>3</effort>
            <velocity>100</velocity>
          </limit>
          <dynamics>
            <damping>0</damping>
            <friction>0.05</friction>
            <spring_reference>0</spring_reference>
            <spring_stiffness>0</spring_stiffness>
          </dynamics>
        </axis>
      </joint>
      <link name='left_front_wheel'>
        <pose relative_to='left_front_wheel_joint'>0 0 0 0 -0 0</pose>
        <inertial>
          <pose>-4e-06 0.000125 1e-06 0 -0 0</pose>
          <mass>0.267401</mass>
          <inertia>
            <ixx>0.0003585</ixx>
            <ixy>0</ixy>
            <ixz>1.3459e-08</ixz>
            <iyy>0.0006846</iyy>
            <iyz>0</iyz>
            <izz>0.0003584</izz>
          </inertia>
        </inertial>
        <collision name='left_front_wheel_collision'>
          <pose>0 0 0 1.5708 -0 0</pose>
          <geometry>
            <cylinder>
              <length>0.02</length>
              <radius>0.055</radius>
            </cylinder>
          </geometry>
          <surface>
            <contact>
              <ode>
                <kp>1e+06</kp>
                <kd>100</kd>
              </ode>
            </contact>
            <friction>
              <ode>
                <mu>1</mu>
                <mu2>1</mu2>
              </ode>
              <torsional>
                <ode/>
              </torsional>
            </friction>
            <bounce/>
          </surface>
          <max_contacts>10</max_contacts>
        </collision>
        <visual name='left_front_wheel_visual'>
          <pose>0 0 0 0 -0 0</pose>
          <geometry>
            <mesh>
              <scale>0.001 0.001 0.001</scale>
              <uri>/home/idris/final_ws/src/rm_description_for_task/meshes/common/swerve_wheel.stl</uri>
            </mesh>
          </geometry>
          <material>
            <script>
              <name>Gazebo/Black</name>
              <uri>file://media/materials/scripts/gazebo.material</uri>
            </script>
          </material>
        </visual>
        <self_collide>0</self_collide>
        <enable_wind>0</enable_wind>
        <kinematic>0</kinematic>
      </link>
      <joint name='right_back_pivot_joint' type='revolute'>
        <pose relative_to='base_link'>-0.181 -0.181 0.013 0 -0 0</pose>
        <parent>base_link</parent>
        <child>right_back_pivot</child>
        <axis>
          <xyz>0 0 1</xyz>
          <limit>
            <lower>-1e+10</lower>
            <upper>1e+10</upper>
            <effort>1.2</effort>
            <velocity>50</velocity>
          </limit>
          <dynamics>
            <damping>0</damping>
            <friction>0.1</friction>
            <spring_reference>0</spring_reference>
            <spring_stiffness>0</spring_stiffness>
          </dynamics>
        </axis>
      </joint>
      <link name='right_back_pivot'>
        <pose relative_to='right_back_pivot_joint'>0 0 0 0 -0 0</pose>
        <inertial>
          <pose>-5e-05 0.017079 -0.041536 0 -0 0</pose>
          <mass>0.114131</mass>
          <inertia>
            <ixx>0.0001335</ixx>
            <ixy>2.6001e-08</ixy>
            <ixz>6.5031e-08</ixz>
            <iyy>0.0001372</iyy>
            <iyz>2.00517e-05</iyz>
            <izz>6.68661e-05</izz>
          </inertia>
        </inertial>
        <visual name='right_back_pivot_visual'>
          <pose>0 0 0 0 -0 0</pose>
          <geometry>
            <mesh>
              <scale>0.001 0.001 0.001</scale>
              <uri>/home/idris/final_ws/src/rm_description_for_task/meshes/common/swerve_pivot.stl</uri>
            </mesh>
          </geometry>
        </visual>
        <self_collide>0</self_collide>
        <enable_wind>0</enable_wind>
        <kinematic>0</kinematic>
      </link>
      <joint name='right_back_wheel_joint' type='revolute'>
        <pose relative_to='right_back_pivot'>0 0 -0.07735 0 -0 0</pose>
        <parent>right_back_pivot</parent>
        <child>right_back_wheel</child>
        <axis>
          <xyz>0 1 0</xyz>
          <limit>
            <lower>-1e+10</lower>
            <upper>1e+10</upper>
            <effort>3</effort>
            <velocity>100</velocity>
          </limit>
          <dynamics>
            <damping>0</damping>
            <friction>0.05</friction>
            <spring_reference>0</spring_reference>
            <spring_stiffness>0</spring_stiffness>
          </dynamics>
        </axis>
      </joint>
      <link name='right_back_wheel'>
        <pose relative_to='right_back_wheel_joint'>0 0 0 0 -0 0</pose>
        <inertial>
          <pose>-4e-06 0.000125 1e-06 0 -0 0</pose>
          <mass>0.267401</mass>
          <inertia>
            <ixx>0.0003585</ixx>
            <ixy>0</ixy>
            <ixz>1.3459e-08</ixz>
            <iyy>0.0006846</iyy>
            <iyz>0</iyz>
            <izz>0.0003584</izz>
          </inertia>
        </inertial>
        <collision name='right_back_wheel_collision'>
          <pose>0 0 0 1.5708 -0 0</pose>
          <geometry>
            <cylinder>
              <length>0.02</length>
              <radius>0.055</radius>
            </cylinder>
          </geometry>
          <surface>
            <contact>
              <ode>
                <kp>1e+06</kp>
                <kd>100</kd>
              </ode>
            </contact>
            <friction>
              <ode>
                <mu>1</mu>
                <mu2>1</mu2>
              </ode>
              <torsional>
                <ode/>
              </torsional>
            </friction>
            <bounce/>
          </surface>
          <max_contacts>10</max_contacts>
        </collision>
        <visual name='right_back_wheel_visual'>
          <pose>0 0 0 0 -0 0</pose>
          <geometry>
            <mesh>
              <scale>0.001 0.001 0.001</scale>
              <uri>/home/idris/final_ws/src/rm_description_for_task/meshes/common/swerve_wheel.stl</uri>
            </mesh>
          </geometry>
          <material>
            <script>
              <name>Gazebo/Black</name>
              <uri>file://media/materials/scripts/gazebo.material</uri>
            </script>
          </material>
        </visual>
        <self_collide>0</self_collide>
        <enable_wind>0</enable_wind>
        <kinematic>0</kinematic>
      </link>
      <joint name='right_front_pivot_joint' type='revolute'>
        <pose relative_to='base_link'>0.181 -0.181 0.013 0 -0 0</pose>
        <parent>base_link</parent>
        <child>right_front_pivot</child>
        <axis>
          <xyz>0 0 1</xyz>
          <limit>
            <lower>-1e+10</lower>
            <upper>1e+10</upper>
            <effort>1.2</effort>
            <velocity>50</velocity>
          </limit>
          <dynamics>
            <damping>0</damping>
            <friction>0.1</friction>
            <spring_reference>0</spring_reference>
            <spring_stiffness>0</spring_stiffness>
          </dynamics>
        </axis>
      </joint>
      <link name='right_front_pivot'>
        <pose relative_to='right_front_pivot_joint'>0 0 0 0 -0 0</pose>
        <inertial>
          <pose>-5e-05 0.017079 -0.041536 0 -0 0</pose>
          <mass>0.114131</mass>
          <inertia>
            <ixx>0.0001335</ixx>
            <ixy>2.6001e-08</ixy>
            <ixz>6.5031e-08</ixz>
            <iyy>0.0001372</iyy>
            <iyz>2.00517e-05</iyz>
            <izz>6.68661e-05</izz>
          </inertia>
        </inertial>
        <visual name='right_front_pivot_visual'>
          <pose>0 0 0 0 -0 0</pose>
          <geometry>
            <mesh>
              <scale>0.001 0.001 0.001</scale>
              <uri>/home/idris/final_ws/src/rm_description_for_task/meshes/common/swerve_pivot.stl</uri>
            </mesh>
          </geometry>
        </visual>
        <self_collide>0</self_collide>
        <enable_wind>0</enable_wind>
        <kinematic>0</kinematic>
      </link>
      <joint name='right_front_wheel_joint' type='revolute'>
        <pose relative_to='right_front_pivot'>0 0 -0.07735 0 -0 0</pose>
        <parent>right_front_pivot</parent>
        <child>right_front_wheel</child>
        <axis>
          <xyz>0 1 0</xyz>
          <limit>
            <lower>-1e+10</lower>
            <upper>1e+10</upper>
            <effort>3</effort>
            <velocity>100</velocity>
          </limit>
          <dynamics>
            <damping>0</damping>
            <friction>0.05</friction>
            <spring_reference>0</spring_reference>
            <spring_stiffness>0</spring_stiffness>
          </dynamics>
        </axis>
      </joint>
      <link name='right_front_wheel'>
        <pose relative_to='right_front_wheel_joint'>0 0 0 0 -0 0</pose>
        <inertial>
          <pose>-4e-06 0.000125 1e-06 0 -0 0</pose>
          <mass>0.267401</mass>
          <inertia>
            <ixx>0.0003585</ixx>
            <ixy>0</ixy>
            <ixz>1.3459e-08</ixz>
            <iyy>0.0006846</iyy>
            <iyz>0</iyz>
            <izz>0.0003584</izz>
          </inertia>
        </inertial>
        <collision name='right_front_wheel_collision'>
          <pose>0 0 0 1.5708 -0 0</pose>
          <geometry>
            <cylinder>
              <length>0.02</length>
              <radius>0.055</radius>
            </cylinder>
          </geometry>
          <surface>
            <contact>
              <ode>
                <kp>1e+06</kp>
                <kd>100</kd>
              </ode>
            </contact>
            <friction>
              <ode>
                <mu>1</mu>
                <mu2>1</mu2>
              </ode>
              <torsional>
                <ode/>
              </torsional>
            </friction>
            <bounce/>
          </surface>
          <max_contacts>10</max_contacts>
        </collision>
        <visual name='right_front_wheel_visual'>
          <pose>0 0 0 0 -0 0</pose>
          <geometry>
            <mesh>
              <scale>0.001 0.001 0.001</scale>
              <uri>/home/idris/final_ws/src/rm_description_for_task/meshes/common/swerve_wheel.stl</uri>
            </mesh>
          </geometry>
          <material>
            <script>
              <name>Gazebo/Black</name>
              <uri>file://media/materials/scripts/gazebo.material</uri>
            </script>
          </material>
        </visual>
        <self_collide>0</self_collide>
        <enable_wind>0</enable_wind>
        <kinematic>0</kinematic>
      </link>
      <plugin name='gazebo_ros_control' filename='libgazebo_ros_control.so'>
        <robotNamespace>/</robotNamespace>
        <robotSimType>gazebo_ros_control/DefaultRobotHWSim</robotSimType>
      </plugin>
      <pose>0 0 0.5 0 -0 0</pose>
    </model>
    <state world_name='default'>
      <sim_time>189 152000000</sim_time>
      <real_time>202 842983815</real_time>
      <wall_time>1763902763 122305713</wall_time>
      <iterations>189152</iterations>
      <model name='ground_plane'>
        <pose>0 0 0 0 -0 0</pose>
        <scale>1 1 1</scale>
        <link name='link'>
          <pose>0 0 0 0 -0 0</pose>
          <velocity>0 0 0 0 -0 0</velocity>
          <acceleration>0 0 0 0 -0 0</acceleration>
          <wrench>0 0 0 0 -0 0</wrench>
        </link>
      </model>
      <model name='sentry'>
        <pose>-0.000131 6e-06 0.119337 -1.2e-05 3e-06 2.3e-05</pose>
        <scale>1 1 1</scale>
        <link name='base_link'>
          <pose>-0.000131 6e-06 0.119337 -1.2e-05 3e-06 2.3e-05</pose>
          <velocity>1.3e-05 -9.1e-05 -0.001829 -0.004362 0.000939 1.5e-05</velocity>
          <acceleration>0 0 -0 0 3e-06 0</acceleration>
          <wrench>0 0 -0 0 -0 0</wrench>
        </link>
        <link name='left_back_pivot'>
          <pose>-0.181134 0.180998 0.132335 -0.000162 -9e-06 0.100217</pose>
          <velocity>5.1e-05 8e-05 -0.00246 -7.6e-05 0.000134 0.000828</velocity>
          <acceleration>0 0 -0 -2.2591 1.16414 0.746363</acceleration>
          <wrench>0 0 -0 0 -0 0</wrench>
        </link>
        <link name='left_back_wheel'>
          <pose>-0.181133 0.18099 0.054983 -0.000203 -0.005858 0.100215</pose>
          <velocity>8e-06 -5.7e-05 -0.002403 0.001032 0.000139 0.000402</velocity>
          <acceleration>0 0 -0 -0.328566 -0.015654 -0.00064</acceleration>
          <wrench>0 0 -0 0 -0 0</wrench>
        </link>
        <link name='left_front_pivot'>
          <pose>0.180864 0.181006 0.132334 -0.000176 1.6e-05 -0.100335</pose>
          <velocity>4.3e-05 7.5e-05 -0.002825 3.6e-05 0.000202 0.00028</velocity>
          <acceleration>0 0 0 -2.17654 -1.3257 -0.783238</acceleration>
          <wrench>0 0 0 0 -0 0</wrench>
        </link>
        <link name='left_front_wheel'>
          <pose>0.180862 0.180997 0.054982 -0.000221 0.000969 -0.100332</pose>
          <velocity>6e-06 -5.9e-05 -0.002769 0.001071 0.000107 0.00016</velocity>
          <acceleration>0 0 0 -0.002414 0.000115 5e-06</acceleration>
          <wrench>0 0 0 0 -0 0</wrench>
        </link>
        <link name='right_back_pivot'>
          <pose>-0.181126 -0.181 0.132338 -8.6e-05 -5e-06 0.099771</pose>
          <velocity>5.4e-05 0.000102 -0.000804 -0.000469 0.000145 0.000771</velocity>
          <acceleration>0 0 0 -2.45102 1.09015 0.703338</acceleration>
          <wrench>0 0 0 0 -0 0</wrench>
        </link>
        <link name='right_back_wheel'>
          <pose>-0.181125 -0.181004 0.054987 -0.00011 -0.005674 0.09977</pose>
          <velocity>1e-05 -4.7e-05 -0.000738 0.000851 0.000168 0.000371</velocity>
          <acceleration>0 0 0 -0.305443 -0.014488 -0.000313</acceleration>
          <wrench>0 0 0 0 -0 0</wrench>
        </link>
        <link name='right_front_pivot'>
          <pose>0.180873 -0.180994 0.132336 2.1e-05 3e-06 -0.001189</pose>
          <velocity>7.2e-05 0.000276 -0.001063 -0.00635 0.001267 -1.3e-05</velocity>
          <acceleration>0 0 0 0.006741 0.002392 -0.003555</acceleration>
          <wrench>0 0 0 0 -0 0</wrench>
        </link>
        <link name='right_front_wheel'>
          <pose>0.180873 -0.180995 0.054986 -9.5e-05 -0.002259 -0.001189</pose>
          <velocity>1e-05 -4.8e-05 -0.001086 0.000877 0.000171 0.000351</velocity>
          <acceleration>0 0 -0 0.036196 -2e-05 -0.002888</acceleration>
          <wrench>0 0 -0 0 -0 0</wrench>
        </link>
      </model>
      <light name='sun'>
        <pose>0 0 10 0 -0 0</pose>
      </light>
    </state>
    <gui fullscreen='0'>
      <camera name='user_camera'>
        <pose>1.09477 -0.781807 0.389402 0 0.275643 2.35619</pose>
        <view_controller>orbit</view_controller>
        <projection_type>perspective</projection_type>
      </camera>
    </gui>
  </world>
</sdf>
